[2025-08-04T21:33:52.764+0000] {taskinstance.py:1957} INFO - Dependencies all met for dep_context=non-requeueable deps ti=<TaskInstance: news_sentiment_dag.fetch_news_and_sentiment scheduled__2025-08-04T21:00:00+00:00 [queued]>
[2025-08-04T21:33:52.773+0000] {taskinstance.py:1957} INFO - Dependencies all met for dep_context=requeueable deps ti=<TaskInstance: news_sentiment_dag.fetch_news_and_sentiment scheduled__2025-08-04T21:00:00+00:00 [queued]>
[2025-08-04T21:33:52.780+0000] {taskinstance.py:2171} INFO - Starting attempt 1 of 2
[2025-08-04T21:33:53.315+0000] {taskinstance.py:2192} INFO - Executing <Task(PythonOperator): fetch_news_and_sentiment> on 2025-08-04 21:00:00+00:00
[2025-08-04T21:33:53.379+0000] {standard_task_runner.py:60} INFO - Started process 235 to run task
[2025-08-04T21:33:53.421+0000] {standard_task_runner.py:87} INFO - Running: ['***', 'tasks', 'run', 'news_sentiment_dag', 'fetch_news_and_sentiment', 'scheduled__2025-08-04T21:00:00+00:00', '--job-id', '3', '--raw', '--subdir', 'DAGS_FOLDER/news_sentiment_dag.py', '--cfg-path', '/tmp/tmpj_fw07ob']
[2025-08-04T21:33:53.496+0000] {standard_task_runner.py:88} INFO - Job 3: Subtask fetch_news_and_sentiment
[2025-08-04T21:33:55.712+0000] {task_command.py:423} INFO - Running <TaskInstance: news_sentiment_dag.fetch_news_and_sentiment scheduled__2025-08-04T21:00:00+00:00 [running]> on host 774479e86811
[2025-08-04T21:33:56.368+0000] {taskinstance.py:2481} INFO - Exporting env vars: AIRFLOW_CTX_DAG_OWNER='***' AIRFLOW_CTX_DAG_ID='news_sentiment_dag' AIRFLOW_CTX_TASK_ID='fetch_news_and_sentiment' AIRFLOW_CTX_EXECUTION_DATE='2025-08-04T21:00:00+00:00' AIRFLOW_CTX_TRY_NUMBER='1' AIRFLOW_CTX_DAG_RUN_ID='scheduled__2025-08-04T21:00:00+00:00'
[2025-08-04T21:33:57.518+0000] {taskinstance.py:2699} ERROR - Task failed with exception
Traceback (most recent call last):
  File "/home/airflow/.local/lib/python3.11/site-packages/urllib3/connectionpool.py", line 467, in _make_request
    self._validate_conn(conn)
  File "/home/airflow/.local/lib/python3.11/site-packages/urllib3/connectionpool.py", line 1092, in _validate_conn
    conn.connect()
  File "/home/airflow/.local/lib/python3.11/site-packages/urllib3/connection.py", line 642, in connect
    sock_and_verified = _ssl_wrap_socket_and_match_hostname(
                        ^^^^^^^^^^^^^^^^^^^^^^^^^^^^^^^^^^^^
  File "/home/airflow/.local/lib/python3.11/site-packages/urllib3/connection.py", line 783, in _ssl_wrap_socket_and_match_hostname
    ssl_sock = ssl_wrap_socket(
               ^^^^^^^^^^^^^^^^
  File "/home/airflow/.local/lib/python3.11/site-packages/urllib3/util/ssl_.py", line 469, in ssl_wrap_socket
    ssl_sock = _ssl_wrap_socket_impl(sock, context, tls_in_tls, server_hostname)
               ^^^^^^^^^^^^^^^^^^^^^^^^^^^^^^^^^^^^^^^^^^^^^^^^^^^^^^^^^^^^^^^^^
  File "/home/airflow/.local/lib/python3.11/site-packages/urllib3/util/ssl_.py", line 513, in _ssl_wrap_socket_impl
    return ssl_context.wrap_socket(sock, server_hostname=server_hostname)
           ^^^^^^^^^^^^^^^^^^^^^^^^^^^^^^^^^^^^^^^^^^^^^^^^^^^^^^^^^^^^^^
  File "/usr/local/lib/python3.11/ssl.py", line 517, in wrap_socket
    return self.sslsocket_class._create(
           ^^^^^^^^^^^^^^^^^^^^^^^^^^^^^
  File "/usr/local/lib/python3.11/ssl.py", line 1108, in _create
    self.do_handshake()
  File "/usr/local/lib/python3.11/ssl.py", line 1383, in do_handshake
    self._sslobj.do_handshake()
ssl.SSLEOFError: [SSL: UNEXPECTED_EOF_WHILE_READING] EOF occurred in violation of protocol (_ssl.c:1006)

During handling of the above exception, another exception occurred:

Traceback (most recent call last):
  File "/home/airflow/.local/lib/python3.11/site-packages/urllib3/connectionpool.py", line 790, in urlopen
    response = self._make_request(
               ^^^^^^^^^^^^^^^^^^^
  File "/home/airflow/.local/lib/python3.11/site-packages/urllib3/connectionpool.py", line 491, in _make_request
    raise new_e
urllib3.exceptions.SSLError: [SSL: UNEXPECTED_EOF_WHILE_READING] EOF occurred in violation of protocol (_ssl.c:1006)

The above exception was the direct cause of the following exception:

Traceback (most recent call last):
  File "/home/airflow/.local/lib/python3.11/site-packages/requests/adapters.py", line 486, in send
    resp = conn.urlopen(
           ^^^^^^^^^^^^^
  File "/home/airflow/.local/lib/python3.11/site-packages/urllib3/connectionpool.py", line 844, in urlopen
    retries = retries.increment(
              ^^^^^^^^^^^^^^^^^^
  File "/home/airflow/.local/lib/python3.11/site-packages/urllib3/util/retry.py", line 515, in increment
    raise MaxRetryError(_pool, url, reason) from reason  # type: ignore[arg-type]
    ^^^^^^^^^^^^^^^^^^^^^^^^^^^^^^^^^^^^^^^^^^^^^^^^^^^
urllib3.exceptions.MaxRetryError: HTTPSConnectionPool(host='finnhub.io', port=443): Max retries exceeded with url: /api/v1/company-news?symbol=AAPL&from=2024-01-01&to=2025-12-31&token=d27rh69r01qr2iat70ngd27rh69r01qr2iat70o0 (Caused by SSLError(SSLEOFError(8, '[SSL: UNEXPECTED_EOF_WHILE_READING] EOF occurred in violation of protocol (_ssl.c:1006)')))

During handling of the above exception, another exception occurred:

Traceback (most recent call last):
  File "/home/airflow/.local/lib/python3.11/site-packages/airflow/models/taskinstance.py", line 433, in _execute_task
    result = execute_callable(context=context, **execute_callable_kwargs)
             ^^^^^^^^^^^^^^^^^^^^^^^^^^^^^^^^^^^^^^^^^^^^^^^^^^^^^^^^^^^^
  File "/home/airflow/.local/lib/python3.11/site-packages/airflow/operators/python.py", line 199, in execute
    return_value = self.execute_callable()
                   ^^^^^^^^^^^^^^^^^^^^^^^
  File "/home/airflow/.local/lib/python3.11/site-packages/airflow/operators/python.py", line 216, in execute_callable
    return self.python_callable(*self.op_args, **self.op_kwargs)
           ^^^^^^^^^^^^^^^^^^^^^^^^^^^^^^^^^^^^^^^^^^^^^^^^^^^^^
  File "/opt/airflow/dags/news_sentiment_dag.py", line 24, in fetch_news_and_sentiment
    news = requests.get(url).json()
           ^^^^^^^^^^^^^^^^^
  File "/home/airflow/.local/lib/python3.11/site-packages/requests/api.py", line 73, in get
    return request("get", url, params=params, **kwargs)
           ^^^^^^^^^^^^^^^^^^^^^^^^^^^^^^^^^^^^^^^^^^^^
  File "/home/airflow/.local/lib/python3.11/site-packages/requests/api.py", line 59, in request
    return session.request(method=method, url=url, **kwargs)
           ^^^^^^^^^^^^^^^^^^^^^^^^^^^^^^^^^^^^^^^^^^^^^^^^^
  File "/home/airflow/.local/lib/python3.11/site-packages/requests/sessions.py", line 589, in request
    resp = self.send(prep, **send_kwargs)
           ^^^^^^^^^^^^^^^^^^^^^^^^^^^^^^
  File "/home/airflow/.local/lib/python3.11/site-packages/requests/sessions.py", line 703, in send
    r = adapter.send(request, **kwargs)
        ^^^^^^^^^^^^^^^^^^^^^^^^^^^^^^^
  File "/home/airflow/.local/lib/python3.11/site-packages/requests/adapters.py", line 517, in send
    raise SSLError(e, request=request)
requests.exceptions.SSLError: HTTPSConnectionPool(host='finnhub.io', port=443): Max retries exceeded with url: /api/v1/company-news?symbol=AAPL&from=2024-01-01&to=2025-12-31&token=d27rh69r01qr2iat70ngd27rh69r01qr2iat70o0 (Caused by SSLError(SSLEOFError(8, '[SSL: UNEXPECTED_EOF_WHILE_READING] EOF occurred in violation of protocol (_ssl.c:1006)')))
[2025-08-04T21:33:57.608+0000] {taskinstance.py:1138} INFO - Marking task as UP_FOR_RETRY. dag_id=news_sentiment_dag, task_id=fetch_news_and_sentiment, execution_date=20250804T210000, start_date=20250804T213352, end_date=20250804T213357
[2025-08-04T21:33:57.677+0000] {standard_task_runner.py:107} ERROR - Failed to execute job 3 for task fetch_news_and_sentiment (HTTPSConnectionPool(host='finnhub.io', port=443): Max retries exceeded with url: /api/v1/company-news?symbol=AAPL&from=2024-01-01&to=2025-12-31&token=d27rh69r01qr2iat70ngd27rh69r01qr2iat70o0 (Caused by SSLError(SSLEOFError(8, '[SSL: UNEXPECTED_EOF_WHILE_READING] EOF occurred in violation of protocol (_ssl.c:1006)'))); 235)
[2025-08-04T21:33:57.706+0000] {local_task_job_runner.py:234} INFO - Task exited with return code 1
[2025-08-04T21:33:57.750+0000] {taskinstance.py:3281} INFO - 0 downstream tasks scheduled from follow-on schedule check
